Workbook

Sheet Sheet1
A1: title | B1: provider | C1: runtime | D1: last updated
A2: erin brockovich | B2: netflix | C2: 131 | D2: =LET(watch,Sheet1!1:1,LAMBDA(x,x)(now())) -> 46046.959
A3: okja | B3: netflix | C3: 120 | D3: =LET(watch,Sheet1!2:2,LAMBDA(x,x)(now())) -> 46046.959
A4: licorice pizza | B4: netflix | C4: 133 | D4: =LET(watch,Sheet1!3:3,LAMBDA(x,x)(now())) -> 46046.959
A5: frankenstein | B5: netflix | C5: 149 | D5: =LET(watch,Sheet1!4:4,LAMBDA(x,x)(now())) -> 46046.959
A6: did you hear about the morgans | B6: netflix | C6: 103 | D6: =LET(watch,Sheet1!5:5,LAMBDA(x,x)(now())) -> 46046.959
A7: moonrise kingdom | B7: netflix | C7: 94 | D7: =LET(watch,Sheet1!6:6,LAMBDA(x,x)(now())) -> 46046.959
A8: 10 dance | B8: netflix | C8: 126 | D8: =LET(watch,Sheet1!7:7,LAMBDA(x,x)(now())) -> 46046.959
A9: dracula | B9: netflix | C9: 127 | D9: =LET(watch,Sheet1!8:8,LAMBDA(x,x)(now())) -> 46046.959
A10: wayward | B10: netflix | D10: =LET(watch,Sheet1!9:9,LAMBDA(x,x)(now())) -> 46046.959
A11: i used to be funny | B11: netflix | C11: 105 | D11: =LET(watch,Sheet1!10:10,LAMBDA(x,x)(now())) -> 46046.959
A12: eddington | B12: hbo max | C12: 148 | D12: =LET(watch,Sheet1!11:11,LAMBDA(x,x)(now())) -> 46046.959
A13: we live in time | B13: hbo max | C13: 108 | D13: =LET(watch,Sheet1!12:12,LAMBDA(x,x)(now())) -> 46046.959
A14: queer | B14: hbo max | C14: 137 | D14: =LET(watch,#REF!,LAMBDA(x,x)(now())) -> 46046.959
A15: uncut gems | B15: hbo max | C15: 135 | D15: =LET(watch,Sheet1!14:14,LAMBDA(x,x)(now())) -> 46046.959
A16: begin again | B16: prime | C16: 104 | D16: =LET(watch,Sheet1!15:15,LAMBDA(x,x)(now())) -> 46046.959
A17: a rainy day in new york | B17: prime | C17: 93 | D17: =LET(watch,Sheet1!16:16,LAMBDA(x,x)(now())) -> 46046.959
A18: four weddings and a funeral | B18: prime | C18: 117 | D18: =LET(watch,Sheet1!17:17,LAMBDA(x,x)(now())) -> 46046.959
A19: the girl next door | B19: prime | C19: 110 | D19: =LET(watch,#REF!,LAMBDA(x,x)(now())) -> 46046.959
A20: me before you | B20: tubi/pluto/free stream | C20: 110 | D20: =LET(watch,Sheet1!19:19,LAMBDA(x,x)(now())) -> 46046.959
A21: bridget jones diary | B21: tubi/pluto/free stream | C21: 97 | D21: =LET(watch,Sheet1!20:20,LAMBDA(x,x)(now())) -> 46046.959
A22: girl interrupted | B22: tubi/pluto/free stream | C22: 127 | D22: =LET(watch,Sheet1!21:21,LAMBDA(x,x)(now())) -> 46046.959
A23: spree | B23: tubi/pluto/free stream | C23: 93 | D23: =LET(watch,Sheet1!22:22,LAMBDA(x,x)(now())) -> 46046.959
A24: truman show | B24: tubi/pluto/free stream | C24: 103 | D24: =LET(watch,Sheet1!23:23,LAMBDA(x,x)(now())) -> 46046.959
A25: interview with the vampire | B25: rent | C25: 123 | D25: =LET(watch,Sheet1!24:24,LAMBDA(x,x)(now())) -> 46046.959
A26: bewitched | B26: rent | C26: 102 | D26: =LET(watch,Sheet1!25:25,LAMBDA(x,x)(now())) -> 46046.959
A27: scooby doo and the witches ghost | B27: rent | C27: 77 | D27: =LET(watch,Sheet1!26:26,LAMBDA(x,x)(now())) -> 46046.959
A28: killers of the flower moon | B28: rent | C28: 206 | D28: =LET(watch,Sheet1!27:27,LAMBDA(x,x)(now())) -> 46046.959
A29: booksmart | B29: rent | C29: 102 | D29: =LET(watch,Sheet1!28:28,LAMBDA(x,x)(now())) -> 46046.959
A30: sleepless in seattle | B30: rent | C30: 105 | D30: =LET(watch,Sheet1!29:29,LAMBDA(x,x)(now())) -> 46046.959
A31: nomad land | B31: rent | C31: 108 | D31: =LET(watch,Sheet1!30:30,LAMBDA(x,x)(now())) -> 46046.959
A32: charliers angels | B32: rent | C32: 98 | D32: =LET(watch,Sheet1!31:31,LAMBDA(x,x)(now())) -> 46046.959
A33: the virgin suicides | B33: rent | C33: 97 | D33: =LET(watch,Sheet1!32:32,LAMBDA(x,x)(now())) -> 46046.959
A34: two weeks notice | B34: rent | C34: 101 | D34: =LET(watch,Sheet1!33:33,LAMBDA(x,x)(now())) -> 46046.959
A35: reality bites | B35: rent | C35: 99 | D35: =LET(watch,Sheet1!34:34,LAMBDA(x,x)(now())) -> 46046.959
A36: wolfwalkers | B36: rent | C36: 103 | D36: =LET(watch,Sheet1!35:35,LAMBDA(x,x)(now())) -> 46046.959
A37: maurice | B37: rent | C37: 140 | D37: =LET(watch,Sheet1!36:36,LAMBDA(x,x)(now())) -> 46046.959
A38: pride + prejudice | B38: rent | C38: 129 | D38: =LET(watch,Sheet1!37:37,LAMBDA(x,x)(now())) -> 46046.959
A39: crazy stupid love | B39: rent | C39: 118 | D39: =LET(watch,Sheet1!38:38,LAMBDA(x,x)(now())) -> 46046.959
A40: dan in real life | B40: rent | C40: 98 | D40: =LET(watch,Sheet1!39:39,LAMBDA(x,x)(now())) -> 46046.959
...
